Workbook

Sheet 使い方
A1: サロン営業リスト（宮崎県全域） 作成日 2026-10-10
A3: ■ 入力するのは黄色の列だけ（ステータス・送信日・送信手段・返信日・備考）。ステータスと送信手段はプルダウン。
A4: ■ 優先度（自動判定・自由に書き換えてOK）
A5: A：電話・LINE・DMの予約や問い合わせを手作業で受けている／開業したばかり → 「施術中も自動で受付」「予約の窓口を一本化」が刺さる
A6: B：ホットペッパーのみで予約 → 「リピーターの再予約をLINEに移して掲載費・手数料を抑える」が刺さる
A7: C：すでに別の予約システム（STORES予約・minimo・自社アプリ等）を使用 → 乗り換え提案になるので後回し
A8: ※ 複数店舗の店は1段階下げています（現行システムは1店舗・1リソース前提のため）
A9: ■ 除外済み：全国チェーン・大手FC、医療機関、休業中の店、既存のお客様（Amarine・Eureka）
A10: ■ 情報は各店が自ら公開している事業用の連絡先のみ。閉店・移転の可能性があるので、送る前に最新情報を確認。
A11: ■ ほとんどの店はHPB掲載のみで、InstagramのIDが空欄。DMで送る前に、Instagram・Googleマップで店名を検索してIDを確認する。
A13: ■ 送るときの注意
A14: ・Instagram DMは1日10〜20件まで（大量送信はアカウント制限のおそれ）
... A18: ・冒頭の「〇〇さんの投稿を拝見して」は1件ずつ書き換える

Sheet リスト
A1: No | B1: 優先度 | C1: 業態 | D1: 市町村 | E1: 店名 | F1: Instagram | G1: メール | H1: 電話 | I1: 公式サイト | J1: 予約方法 | K1: HPB掲載 | L1: 規模 | M1: メモ | N1: 出典 | O1: ステータス | P1: 送信日 | Q1: 送信手段 | R1: 返信日 | S1: 次のアクション・備考
A2: 1 | B2: A | C2: リラク・マッサージ | D2: 延岡市 | E2: アロマリラクゼーション＆エステティックサロン 健康くらぶ | F2: https://www.instagram.com/momihogushiaroma/ | J2: HPB（即時予約）/電話/飛び込み可 | K2: https://beauty.hotpepper.jp/kr/slnH000624645/ | L2: 個人/小規模 | M2: もみほぐし・オイル＋エステ・まつげ。5名・ベッド4、23時まで。シニア・男性客も多くLINE配信での再来促進が有効そう | O2: 未送信
A3: 2 | B3: A | C3: リラク・マッサージ | D3: 宮崎市 | E3: Chanvre Belle【シャンヴルベル】 | F3: https://www.instagram.com/chanvrebelle/ | J3: HPB/電話 | K3: https://beauty.hotpepper.jp/kr/slnH000698541/ | L3: 個人/小規模 | M3: 理学療法士オーナーの1人サロン（整体系リラク＋もみほぐし＋よもぎ蒸し）。電話は予約専用・営業電話不可と明記→DM/メールで ／連絡先メモ: 公式LINEで予約受付ありと記載（ID未掲載） | O3: 未送信
A4: 3 | B4: A | C4: リラク・マッサージ | D4: 宮崎市 | E4: Hardy-Hearts【ハーディハーツ】 | F4: https://www.instagram.com/hardyhearts.m/ | J4: HPB/電話（ペア割は電話のみ） | K4: https://beauty.hotpepper.jp/kr/slnH000680005/ | L4: 個人/小規模 | M4: ヘッドスパ（ドライ/アーユルヴェーダ）中心、スタッフ4人。HPB備考の公式サイトURLがサンプル風ドメインで実在不明のため空欄 ／連絡先メモ: 公式LINE: https://lin.ee/DFg2HMG / TEL 0985-27-3300（公式サイト記載） | O4: 未送信
A5: 4 | B5: A | C5: リラク・マッサージ | D5: 宮崎市 | E5: Spa Air【スパアイル】 | J5: HPB（ネット予約推奨）/電話/SMS | K5: https://beauty.hotpepper.jp/kr/slnH000727663/ | L5: 個人/小規模 | M5: バリ式・ヘッドスパ。1人営業。電話に出られない時はSMSで、と案内＝連絡手段の分散を一本化できるLINE予約が刺さる | O5: 未送信
A6: 5 | B6: A | C6: リラク・マッサージ | D6: 宮崎市 | E6: ココタイ ロムエシア（COCOTHAI） | F6: https://www.instagram.com/cocothai_romasia/ | J6: HPB（即時予約）/電話（20時以降は電話） | K6: https://beauty.hotpepper.jp/kr/slnH000216849/ | L6: 個人/小規模 | M6: タイ古式×オイル。施術者5人・半個室5。口コミ4.88(179件)。HPBに「新規会員登録は2026年3月で終了」との記載あり＝既存客中心の運用に移行？LINE会員化の提案余地 ／連絡先メモ: 検索スニペットのTEL 0985-31-5517（未検証） | O6: 未送信
A7: 6 | B7: A | C7: リラク・マッサージ | D7: 宮崎市 | E7: タイ古式ボディーケア natural body care | H7: 090-3328-7784 | J7: 電話（出張予約含む） | L7: 個人/小規模 | M7: HPB非掲載・電話予約中心で有望。宮崎市内・近郊への出張対応あり。エキテン口コミ4.51(32件)。電話番号はエキテン掲載ページ由来、営業時間表記が媒体で不一致→要確認 ／連絡先メモ: メール naturalbody@ymail.ne.jp（公式サイト記載）/ Facebook https://www.facebook.com/tmnaturalbody/ / Twitter @naturalbody1 / TEL 090-3328-7784 | N7: https://www.ekiten.jp/shop_3070554/ | O7: 未送信
A8: 7 | B8: A | C8: リラク・マッサージ | D8: 宮崎市 | E8: タイ古式ボディケア treat【トリート】 | F8: https://www.instagram.com/treat.tori/ | J8: HPB/電話 | K8: https://beauty.hotpepper.jp/kr/slnH000769392/ | L8: 個人/小規模 | M8: 施術者1人・ベッド1。施術中は電話に出られない旨明記＝LINE自動予約で取りこぼし防止が刺さる。当日キャンセル100%規定あり（リマインド機能訴求） | O8: 未送信
A9: 8 | B9: A | C9: リラク・マッサージ | D9: 宮崎市 | E9: ドライヘッドスパ専門店 ころん | J9: HPB/電話 | K9: https://beauty.hotpepper.jp/kr/slnH000743101/ | L9: 個人/小規模 | M9: ★営業電話お断り→DM/メールで。 スタッフ1人。施術中は電話不可と明記。「営業電話お断り」記載あり→電話は避けDM/メールで丁寧に ／連絡先メモ: LINE公式 @206irqov（Yahoo!マップ https://map.yahoo.co.jp/v3/place/kPzIIwi8cqk 掲載）、TEL 080-3212-8032 | O9: 未送信
A10: 9 | B10: A | C10: リラク・マッサージ | D10: 宮崎市 | E10: ヘッドスパ専門店 癒しの刻 | J10: HPB/電話（ネット満枠時・2名予約は電話） | K10: https://beauty.hotpepper.jp/kr/slnH000537334/ | L10: 個人/小規模 | M10: ドライ/オイル/クリーム/スカルプの4種ヘッドスパ。完全個室2。「ネットで×でも電話なら空いている場合あり」＝HPB枠と実枠がズレている | O10: 未送信
A11: 10 | B11: A | C11: リラク・マッサージ | D11: 宮崎市 | E11: ほぐし手ゆらり | F11: https://www.instagram.com/yu.ra.ri_/（候補・要確認） | J11: HPB/電話（当日は電話推奨） | K11: https://beauty.hotpepper.jp/kr/slnH000337362/ | L11: 個人/小規模 | M11: 女性ベテランセラピスト7〜8人・ベッド4、指名料なし、22時まで。当日予約は電話が確実と案内＝電話対応負荷が高い ／連絡先メモ: LINE公式 https://page.line.me/nyq8441v / Facebook https://www.facebook.com/yurari1103/ / TEL 0985-74-6266 | O11: 未送信
A12: 11 | B12: A | C12: リラク・マッサージ | D12: 宮崎市 | E12: もみほぐしと癒しのサロン Bel Salone | F12: https://www.instagram.com/bel_salone_2025/ | J12: HPB（即時予約）/電話（ペア予約は電話） | K12: https://beauty.hotpepper.jp/kr/slnH000753497/ | L12: 個人/小規模 | M12: セラピスト3人・ベッド3。もみほぐし＋ドライヘッドスパ、22時まで営業。ペア予約は電話のみ＝LINEで複数名予約を受けられる点が訴求ポイント | O12: 未送信
A13: 12 | B13: A | C13: リラク・マッサージ | D13: 宮崎市 | E13: らく～な【ラクーナ】 | F13: https://www.instagram.com/rakuna0918/ | J13: HPB/電話 | K13: https://beauty.hotpepper.jp/kr/slnH000664889/ | L13: 個人/小規模 | M13: 2023年9月開業の女性1人サロン。アロマオイル（5種から選択）、完全個室・男女OK ／連絡先メモ: TEL 090-3074-5556 | O13: 未送信
A14: 13 | B14: A | C14: リラク・マッサージ | D14: 宮崎市 | E14: リラクゼーション Bloom【ブルーム】 | J14: HPB/電話 | K14: https://beauty.hotpepper.jp/kr/slnH000804431/ | L14: 個人/小規模 | M14: 新規オープン。アーユルヴェーダ（アビヤンガ）オイル。1人・完全個室。開業初期で集客/予約導線を整えたい時期 | O14: 未送信
A15: 14 | B15: A | C15: リラク・マッサージ | D15: 宮崎市 | E15: リラクゼーションサロン .Nature.【ナチュール】 | J15: HPB/電話 | K15: https://beauty.hotpepper.jp/kr/slnH000639191/ | L15: 個人/小規模 | M15: 1人・完全個室。施術中は電話に出られない旨記載＝LINE自動受付の訴求ポイント | O15: 未送信
A16: 15 | B16: A | C16: リラク・マッサージ | D16: 宮崎市 | E16: リラクゼーションサロン Monstera【モンステラ】 | J16: HPB（即時予約）/電話 | K16: https://beauty.hotpepper.jp/kr/slnH000513328/ | L16: 個人/小規模 | M16: タイ古式×オイル。セラピスト歴15年のオーナー1人・完全個室1室。口コミ4.97(120件)と高評価＝リピーター管理/LINE再来促進の訴求が効きそう | O16: 未送信
A17: 16 | B17: A | C17: リラク・マッサージ | D17: 宮崎市（清武町） | E17: ぬくい手【ヌクイテ】 | J17: HPB（即時予約）/電話 | K17: https://beauty.hotpepper.jp/kr/slnH000640192/ | L17: 個人/小規模 | M17: 1人営業、肩もみ＋ドライヘッドスパ。施術中は電話に出られない旨記載。支払いは現金/PayPay | O17: 未送信
A18: 17 | B18: A | C18: リラク・マッサージ | D18: 都城市 | E18: re mano heal【リマーノヒール】 | J18: HPB（即時予約）/電話/LINE公式（@797nmmky・道案内用） | K18: https://beauty.hotpepper.jp/kr/slnH000818078/ | L18: 個人/小規模 | M18: LINE公式アカウント保有（HPB記載）だが予約はHPB＝LINE予約化の最有力。女性専用・歴10年超のオーナー1人、土日は問い合わせ対応 ／連絡先メモ: LINE公式 @797nmmky（HPBアクセス欄に『公式LINE @797nmmky よりご連絡ください』） | O18: 未送信
A19: 18 | B19: A | C19: リラク・マッサージ | D19: 都城市 | E19: Ring リラクゼーション【リング】 | J19: HPB（即時予約）/電話/LINE問い合わせ | K19: https://beauty.hotpepper.jp/kr/slnH000448069/ | L19: 個人/小規模 | M19: HPBに「LINEでのお問い合わせ可」と記載（LINE IDは非掲載）＝既にLINEで手動対応→予約自動化の提案が通りやすい。施術中は折り返し対応 ／連絡先メモ: HPBに『LINEでのお問い合わせ可』記載（ID未掲載）/ TEL 090-3884-6368（ディレクトリ掲載） | O19: 未送信
A20: 19 | B20: A | C20: リラク・マッサージ | D20: 日向市 | E20: リラクゼーション クロユリ | J20: HPB（即時予約） | K20: https://beauty.hotpepper.jp/kr/slnH000386545/ | L20: 個人/小規模 | M20: 女性専用・1人営業・個室。電話番号非掲載でHPBのみ受付。時間外も事前連絡で対応＝個別調整をLINEで受けられる提案 ／連絡先メモ: 公式サイト(Wix): https://kurokimitiharu.wixsite.com/kuroyuri | O20: 未送信
A21: 20 | B21: A | C21: リラク・マッサージ | D21: 日南市 | E21: Natural Therapy FIKA【フィーカ】 | J21: HPB（即時予約）/電話 | K21: https://beauty.hotpepper.jp/kr/slnH000789906/ | L21: 個人/小規模 | M21: アロマ＋ホットストーンのプライベートサロン、1人。口コミ0件の新店＝立ち上げ期。住所を予約後に送る運用はLINE自動送信と相性良 | O21: 未送信
A22: 21 | B22: A | C22: エステ | D22: 延岡市 | E22: 脱毛専門サロンSPICA | J22: HPB | K22: https://beauty.hotpepper.jp/kr/slnH000639632/ | L22: 個人/小規模 | M22: 脱毛専門(VIO・顔・髭・全身)のひとりサロン。口コミ5.00(14件)。脱毛は周期来店→LINEリマインドの訴求が合う | O22: 未送信
A23: 22 | B23: A | C23: エステ | D23: 宮崎市 | E23: total beauty salon BISUKA | F23: https://www.instagram.com/bisuka_miyazaki/ | J23: HPB/LINE公式(ID非公開) | K23: https://beauty.hotpepper.jp/kr/slnH000535505/ | L23: 個人/小規模 | M23: 韓国式フェイシャル・小顔・全身脱毛・温熱デトックス。2名。公式LINEで連絡受付の案内あり(予約機能の有無は不明)。2階にFUN(ピラティス) ／連絡先メモ: LINE公式 @jzh0152e（https://line.me/R/ti/p/%40jzh0152e）/ Facebook https://www.facebook.com/salon.bisuka/ | O23: 未送信
A24: 23 | B24: A | C24: エステ | D24: 宮崎市 | E24: yoru aesthe【ヨルエステ】 | F24: @yoruaesthe_miyazaki_ | J24: HPB/LINE(時間外問合せ) | K24: https://beauty.hotpepper.jp/kr/slnH000776287/ | L24: 個人/小規模 | M24: 小顔矯正・ハーブ・肌質改善・美容整体・ブライダル。1名・1台。夜営業×時間外はLINE問合せ→自動予約受付が刺さる。口コミ4.92(80件) | O24: 未送信
A25: 24 | B25: A | C25: エステ | D25: 宮崎市 | E25: ブライダル＆本格リンパケア専門 1ST MIYAZAKI | F25: @miyazaki_1st | J25: HPB/LINE(料金案内あり・ID非公開) | K25: https://beauty.hotpepper.jp/kr/slnH000535411/ | L25: 個人/小規模 | M25: ブライダル専門色が強い(フェイシャル+背中シェービング等)＋脂肪燃焼マシン痩身。2名。口コミ4.95(46件)。Instagramで休業・駐車場案内 | O25: 未送信
A26: 25 | B26: A | C26: エステ | D26: 宮崎市 | E26: 大人女性のためのフェイシャル専門店 Chouchou【シュシュ】 | F26: https://www.instagram.com/chou_chou0615/ | J26: HPB | K26: https://beauty.hotpepper.jp/kr/slnH000757423/ | L26: 個人/小規模 | M26: フェイシャル専門のひとりサロン(1名・1台)。口コミ4.99(178件)。施術中に電話に出られない一人営業→LINE自動予約の訴求が合う ／連絡先メモ: サブIG: https://www.instagram.com/chouchou_0615/ （宮崎市の雑貨店 chouchou_miyazaki_ と www.esthe-chouchou.net は別店） | O26: 未送信
A27: 26 | B27: A | C27: エステ | D27: 宮崎市 | E27: 脱毛×韓国肌管理専門店 ツルリ | F27: https://www.instagram.com/tururiii/ | J27: HPB/LINE公式(@ihl0790y) | K27: https://beauty.hotpepper.jp/kr/slnH000420315/ | L27: 個人/小規模 | M27: ★営業電話お断り→DM/メールで。 既にLINE公式で予約・問合せ受付。電話は不可・営業電話お断りと明記→メール/DMで。スタッフ2名 ／連絡先メモ: LINE公式 @ihl0790y（HPB・公式サイト両方に記載）、Facebook https://www.facebook.com/tururiii/ | O27: 未送信
A28: 27 | B28: A | C28: 美容室 | D28: 延岡市 | E28: Back Drop（バックドロップ） | H28: 090-3576-2822 | J28: HPB（一部メニュー）/電話（一般クーポンはネット予約不可） | K28: https://beauty.hotpepper.jp/slnH000690878/ | L28: 小規模（スタイリスト2・2席） | M28: 一般クーポンはネット予約不可で電話予約（番号はHPB掲載）→電話依存解消のLINE予約が最も刺さる候補 | O28: 未送信
A29: 28 | B29: A | C29: 美容室 | D29: 延岡市 | E29: miree Hair Comfort（ミレーヘアコンフォート） | J29: HPB（ネット予約） | K29: https://beauty.hotpepper.jp/slnH000818972/ | L29: 個人（スタイリスト1・2席） | M29: 女性オーナーの新規開業プライベートサロン・完全予約制 | O29: 未送信
A30: 29 | B30: A | C30: 美容室 | D30: 宮崎市 | E30: TERRACE（テラス） | J30: HPB（ネット予約） | K30: https://beauty.hotpepper.jp/slnH000122215/ | L30: 個人/小規模（スタイリスト2・2席） | M30: 南宮崎駅徒歩2分。オーナーマンツーマン、19時以降の当日枠あり→当日空き枠のLINE配信がフック | O30: 未送信
A31: 30 | B31: A | C31: 美容室 | D31: 三股町 | E31: SWAG（スワッグ） | J31: HPB（ネット予約） | K31: https://beauty.hotpepper.jp/slnH000749997/ | L31: 個人（スタイリスト1・4席） | M31: 新規オープン（移転）・個室あり・マンツーマン | O31: 未送信
A32: 31 | B32: A | C32: 美容室 | D32: 都城市 | E32: Lea lea（レアレア） | J32: HPB（ネット予約） | K32: https://beauty.hotpepper.jp/slnH000806402/ | L32: 個人（スタイリスト1・1席） | M32: 2026年4月開業の1席マンツーマン。新規開業で集客・予約導線づくり期→初期0円訴求が効きやすい | O32: 未送信
A33: 32 | B33: A | C33: ネイル | D33: 延岡市 | E33: Jia nail（ジアネイル） | F33: @jianail.saya | J33: HPB | K33: https://beauty.hotpepper.jp/kr/slnH000799811/ | L33: 個人/小規模 | M33: 1人運営・完全貸切。顧客限定リペア無料→リピーター管理をLINEで、の訴求が合う。Instagram IDはHPB投稿文より | O33: 未送信
A34: 33 | B34: A | C34: ネイル | D34: 宮崎市 | E34: Linon（リノン） | F34: https://www.instagram.com/linon__nail/ | J34: HPB | K34: https://beauty.hotpepper.jp/kr/slnH000706575/ | L34: 個人/小規模 | M34: ネイリスト2名の戸建てプライベートサロン。口コミ4.97(71件)。毎月変わる定額デザイン→LINEでの新作配信と相性良 ／連絡先メモ: ネイリスト個人 https://www.instagram.com/na.3.nail/ （スタッフ個人・SUN記事掲載） | O34: 未送信
A35: 34 | B35: A | C35: ネイル | D35: 宮崎市 | E35: melily（メリリ） | F35: https://www.instagram.com/nail.melily/ | J35: HPB | K35: https://beauty.hotpepper.jp/kr/slnH000805193/ | L35: 個人/小規模 | M35: 1人・1席、女性専用・個室。新規オープン系の打ち出し ／連絡先メモ: ネイリスト niina | O35: 未送信
A36: 35 | B36: A | C36: ネイル | D36: 宮崎市 | E36: nail studio BUBBLES（ネイルスタジオバブルス） | J36: HPB | K36: https://beauty.hotpepper.jp/kr/slnH000812830/ | L36: 個人/小規模 | M36: 1人・1席の完全個室、10-22時営業。福岡で15年の経歴をアピール（移転開業組） | O36: 未送信
A37: 36 | B37: A | C37: ネイル | D37: 宮崎市 | E37: purplerabbit（パープルラビット） | F37: @purple_rabbit91 | J37: HPB / Instagram DM（時間外問い合わせ） | K37: https://beauty.hotpepper.jp/kr/slnH000739389/ | L37: 個人/小規模 | M37: 1人・1席、平日8:30-16:30のみ。時間外はInstagram DM対応と明記。ただし現在新規受付停止中（優先度低、既存客管理の切り口なら可） | O37: 未送信
A38: 37 | B38: A | C38: ネイル | D38: 西都市 | E38: moto nail（モトネイル） | J38: HPB / LINE（問い合わせ） | K38: https://beauty.hotpepper.jp/kr/slnH000786936/ | L38: 個人/小規模 | M38: 1人・1席の集合住宅内サロン。施術中は電話に出られずLINE問い合わせ案内→LINE予約自動化の訴求ど真ん中。現金のみ、口コミ4.86(43件) | O38: 未送信
A39: 38 | B39: A | C39: ネイル | D39: 都城市 | E39: &Knail（アンドケーネイル） | J39: HPB | K39: https://beauty.hotpepper.jp/kr/slnH000809814/ | L39: 個人/小規模 | M39: 2025年5月オープンの新店、口コミ4.97(34件)。無断キャンセル料50%規定あり→LINEリマインドの訴求が刺さりやすい | O39: 未送信
A40: 39 | B40: A | C40: ネイル | D40: 門川町 | E40: remyu.（レミュー） | F40: https://www.instagram.com/remyu_manae/ | J40: HPB / LINE公式 / Instagram（ID非掲載） | K40: https://beauty.hotpepper.jp/kr/slnH000707044/ | L40: 個人/小規模 | M40: スタッフ1名・完全予約制。HPB上でInstagramと公式LINEがあると記載（ID非掲載）。新規は平日のみ受付→予約導線を整理する提案余地 ／連絡先メモ: 公式LINE: https://lin.ee/Nt1mixF（LINE ID @830ourog、remyu./nail/kadogawa） | O40: 未送信
...

Sheet 集計
A1: 業態 × ステータス
A2: 業態 | B2: 未送信 | C2: 送信済 | D2: 返信あり | E2: 商談 | F2: 受注 | G2: 見送り | H2: 合計
A3: リラク・マッサージ | B3: =COUNTIFS(リスト!$C:$C,$A3,リスト!$O:$O,B$2) | C3: =COUNTIFS(リスト!$C:$C,$A3,リスト!$O:$O,C$2) | D3: =COUNTIFS(リスト!$C:$C,$A3,リスト!$O:$O,D$2) | E3: =COUNTIFS(リスト!$C:$C,$A3,リスト!$O:$O,E$2) | F3: =COUNTIFS(リスト!$C:$C,$A3,リスト!$O:$O,F$2) | G3: =COUNTIFS(リスト!$C:$C,$A3,リスト!$O:$O,G$2) | H3: =SUM(B3:G3)
A4: エステ | B4: =COUNTIFS(リスト!$C:$C,$A4,リスト!$O:$O,B$2) | C4: =COUNTIFS(リスト!$C:$C,$A4,リスト!$O:$O,C$2) | D4: =COUNTIFS(リスト!$C:$C,$A4,リスト!$O:$O,D$2) | E4: =COUNTIFS(リスト!$C:$C,$A4,リスト!$O:$O,E$2) | F4: =COUNTIFS(リスト!$C:$C,$A4,リスト!$O:$O,F$2) | G4: =COUNTIFS(リスト!$C:$C,$A4,リスト!$O:$O,G$2) | H4: =SUM(B4:G4)
A5: 美容室 | B5: =COUNTIFS(リスト!$C:$C,$A5,リスト!$O:$O,B$2) | C5: =COUNTIFS(リスト!$C:$C,$A5,リスト!$O:$O,C$2) | D5: =COUNTIFS(リスト!$C:$C,$A5,リスト!$O:$O,D$2) | E5: =COUNTIFS(リスト!$C:$C,$A5,リスト!$O:$O,E$2) | F5: =COUNTIFS(リスト!$C:$C,$A5,リスト!$O:$O,F$2) | G5: =COUNTIFS(リスト!$C:$C,$A5,リスト!$O:$O,G$2) | H5: =SUM(B5:G5)
A6: ネイル | B6: =COUNTIFS(リスト!$C:$C,$A6,リスト!$O:$O,B$2) | C6: =COUNTIFS(リスト!$C:$C,$A6,リスト!$O:$O,C$2) | D6: =COUNTIFS(リスト!$C:$C,$A6,リスト!$O:$O,D$2) | E6: =COUNTIFS(リスト!$C:$C,$A6,リスト!$O:$O,E$2) | F6: =COUNTIFS(リスト!$C:$C,$A6,リスト!$O:$O,F$2) | G6: =COUNTIFS(リスト!$C:$C,$A6,リスト!$O:$O,G$2) | H6: =SUM(B6:G6)
A7: まつげ | B7: =COUNTIFS(リスト!$C:$C,$A7,リスト!$O:$O,B$2) | C7: =COUNTIFS(リスト!$C:$C,$A7,リスト!$O:$O,C$2) | D7: =COUNTIFS(リスト!$C:$C,$A7,リスト!$O:$O,D$2) | E7: =COUNTIFS(リスト!$C:$C,$A7,リスト!$O:$O,E$2) | F7: =COUNTIFS(リスト!$C:$C,$A7,リスト!$O:$O,F$2) | G7: =COUNTIFS(リスト!$C:$C,$A7,リスト!$O:$O,G$2) | H7: =SUM(B7:G7)
A8: 合計 | B8: =SUM(B3:B7) | C8: =SUM(C3:C7) | D8: =SUM(D3:D7) | E8: =SUM(E3:E7) | F8: =SUM(F3:F7) | G8: =SUM(G3:G7) | H8: =SUM(H3:H7)
A10: 返信率 | B10: =IFERROR((D8+E8+F8)/(C8+D8+E8+F8+G8),0)
A11: ※ 返信あり・商談・受注 ÷ 送信した数（見送りも送信済として分母に含む）
